Workbook

Sheet Mandatory Assigment 
A1: a) Prices | B1: BAC | C1: CVX | D1: DELL | E1: EQNR | F1: MSFT
A2: 43832 | B2: 30.587564 | C2: 92.017715 | D2: 24.189837 | E2: 13.323237 | F2: 152.15842 | H2: Returns | I2: {=B1:F1} -> BAC | J2: CVX | K2: DELL | L2: EQNR | M2: MSFT | N2: Market port | P2: b) | Q2: {=_xlfn.ANCHORARRAY(I2)} -> BAC | R2: CVX | S2: DELL | T2: EQNR | U2: MSFT | V2: Market | W2: Riske free | X2: Risk Premium market | AI2: Covariance Inverse | AJ2: {=_xlfn.ANCHORARRAY(AC3)} -> BAC | AK2: CVX | AL2: DELL | AM2: EQNR | AN2: MSFT
A3: 43833 | B3: 29.952465 | C3: 91.699455 | D3: 23.39415 | E3: 13.362363 | F3: 150.26373 | I3: =B3/B2-1 -> -0.020763321 | J3: =C3/C2-1 -> -0.0034586839 | K3: =D3/D2-1 -> -0.032893431 | L3: =E3/E2-1 -> 0.0029366318 | M3: =F3/F2-1 -> -0.012452048 | N3: =SUMPRODUCT(I3:M3,$AJ$13:$AN$13) -> -0.013795763 | P3: Exp. Return | Q3: =AVERAGE(I3:I1563) -> 0.00050824625 | R3: =AVERAGE(J3:J1563) -> 0.00073023905 | S3: =AVERAGE(K3:K1563) -> 0.0016240008 | T3: =AVERAGE(L3:L1563) -> 0.0010216171 | U3: =AVERAGE(M3:M1563) -> 0.00076485382 | V3: =AVERAGE(N3:N1563) -> 0.0014075108 | W3: 0.0001 | X3: =V3-W3 -> 0.0013075108 | AB3: j) | AC3: {=_xlfn.ANCHORARRAY(Y19)} -> BAC | AD3: CVX | AE3: DELL | AF3: EQNR | AG3: MSFT | AI3: {=TRANSPOSE(_xlfn.ANCHORARRAY(AC3))} -> BAC | AJ3: {=MINVERSE(Q9:U13)} -> 3803.1796 | AK3: -1824.5953 | AL3: -327.74689 | AM3: -138.36903 | AN3: -892.45799
A4: 43836 | B4: 29.909559 | C4: 91.388794 | D4: 23.630077 | E4: 13.668873 | F4: 150.65213 | I4: =B4/B3-1 -> -0.0014324633 | J4: =C4/C3-1 -> -0.0033878207 | K4: =D4/D3-1 -> 0.010084897 | L4: =E4/E3-1 -> 0.022938306 | M4: =F4/F3-1 -> 0.0025847702 | N4: =SUMPRODUCT(I4:M4,$AJ$13:$AN$13) -> 0.017357712 | P4: Variance | Q4: =_xlfn.VAR.S(I3:I1563) -> 0.00046288343 | R4: =_xlfn.VAR.S(J3:J1563) -> 0.00045048727 | S4: =_xlfn.VAR.S(K3:K1563) -> 0.00085740571 | T4: =_xlfn.VAR.S(L3:L1563) -> 0.00057922312 | U4: =_xlfn.VAR.S(M3:M1563) -> 0.00035034547 | V4: =_xlfn.VAR.S(N3:N1563) -> 0.00046277347 | AB4: Covariances | AC4: =_xlfn.COVARIANCE.S(I3:I1563,$N$3:$N$1563) -> 0.00014449252 | AD4: =_xlfn.COVARIANCE.S(J3:J1563,$N$3:$N$1563) -> 0.00022306348 | AE4: =_xlfn.COVARIANCE.S(K3:K1563,$N$3:$N$1563) -> 0.00053939679 | AF4: =_xlfn.COVARIANCE.S(L3:L1563,$N$3:$N$1563) -> 0.0003261923 | AG4: =_xlfn.COVARIANCE.S(M3:M1563,$N$3:$N$1563) -> 0.00023531485 | AI4: CVX | AJ4: -1824.5953 | AK4: 5593.2772 | AL4: -221.45344 | AM4: -2637.4201 | AN4: -157.4096
A5: 43837 | B5: 29.712162 | C5: 90.221779 | D5: 23.037937 | E5: 13.512358 | F5: 149.27853 | I5: =B5/B4-1 -> -0.0065998041 | J5: =C5/C4-1 -> -0.012769783 | K5: =D5/D4-1 -> -0.02505875 | L5: =E5/E4-1 -> -0.011450478 | M5: =F5/F4-1 -> -0.0091176686 | N5: =SUMPRODUCT(I5:M5,$AJ$13:$AN$13) -> -0.019116324 | P5: S.Dev | Q5: =SQRT(Q4) -> 0.021514726 | R5: =SQRT(R4) -> 0.021224685 | S5: =SQRT(S4) -> 0.029281491 | T5: =SQRT(T4) -> 0.024067055 | U5: =SQRT(U4) -> 0.018717518 | V5: =SQRT(V4) -> 0.02151217 | AB5: Beta | AC5: =AC4/$V$4 -> 0.31223165 | AD5: =AD4/$V$4 -> 0.48201441 | AE5: =AE4/$V$4 -> 1.1655741 | AF5: =AF4/$V$4 -> 0.70486387 | AG5: =AG4/$V$4 -> 0.5084882 | AI5: DELL | AJ5: -327.74689 | AK5: -221.45344 | AL5: 1540.9821 | AM5: -105.60662 | AN5: -760.6457
A6: 43838 | B6: 30.012543 | C6: 89.191193 | D6: 23.130465 | E6: 13.408013 | F6: 151.65633 | I6: =B6/B5-1 -> 0.010109689 | J6: =C6/C5-1 -> -0.01142281 | K6: =D6/D5-1 -> 0.0040163053 | L6: =E6/E5-1 -> -0.0077221437 | M6: =F6/F5-1 -> 0.015928562 | N6: =SUMPRODUCT(I6:M6,$AJ$13:$AN$13) -> 0.0012542043 | P6: Value at risk 10% | Q6: =_xlfn.PERCENTILE.EXC(I3:I1563,10%) -> -0.021608485 | R6: =_xlfn.PERCENTILE.EXC(J3:J1563,10%) -> -0.020598744 | S6: =_xlfn.PERCENTILE.EXC(K3:K1563,10%) -> -0.02715083 | T6: =_xlfn.PERCENTILE.EXC(L3:L1563,10%) -> -0.025163198 | U6: =_xlfn.PERCENTILE.EXC(M3:M1563,10%) -> -0.020129223 | V6: =_xlfn.PERCENTILE.EXC(N3:N1563,10%) -> -0.021427956 | AI6: EQNR | AJ6: -138.36903 | AK6: -2637.4201 | AL6: -105.60662 | AM6: 3455.5824 | AN6: 23.971671
A7: 43839 | B7: 30.064032 | C7: 89.047218 | D7: 22.954668 | E7: 13.479752 | F7: 153.55099 | I7: =B7/B6-1 -> 0.0017155786 | J7: =C7/C6-1 -> -0.0016142211 | K7: =D7/D6-1 -> -0.0076002152 | L7: =E7/E6-1 -> 0.0053504006 | M7: =F7/F6-1 -> 0.012493172 | N7: =SUMPRODUCT(I7:M7,$AJ$13:$AN$13) -> 0.0022727955 | AB7: Required returns | AC7: =$W$3+$X$3*AC5 -> 0.00050824625 | AD7: =$W$3+$X$3*AD5 -> 0.00073023905 | AE7: =$W$3+$X$3*AE5 -> 0.0016240008 | AF7: =$W$3+$X$3*AF5 -> 0.0010216171 | AG7: =$W$3+$X$3*AG5 -> 0.00076485382 | AI7: MSFT | AJ7: -892.45799 | AK7: -157.4096 | AL7: -760.6457 | AM7: 23.971671 | AN7: 3828.0474
A8: 43840 | B8: 29.815144 | C8: 88.236389 | D8: 22.903784 | E8: 13.329755 | F8: 152.84045 | I8: =B8/B7-1 -> -0.0082785975 | J8: =C8/C7-1 -> -0.0091056091 | K8: =D8/D7-1 -> -0.0022167276 | L8: =E8/E7-1 -> -0.011127561 | M8: =F8/F7-1 -> -0.0046273928 | N8: =SUMPRODUCT(I8:M8,$AJ$13:$AN$13) -> -0.00520678 | P8: Covar | Q8: BAC | R8: CVX | S8: DELL | T8: EQNR | U8: MSFT
A9: 43843 | B9: 30.089783 | C9: 88.403091 | D9: 23.051817 | E9: 13.362363 | F9: 154.67831 | I9: =B9/B8-1 -> 0.0092113972 | J9: =C9/C8-1 -> 0.001889269 | K9: =D9/D8-1 -> 0.0064632614 | L9: =E9/E8-1 -> 0.002446259 | M9: =F9/F8-1 -> 0.012024697 | N9: =SUMPRODUCT(I9:M9,$AJ$13:$AN$13) -> 0.0057991203 | P9: BAC | Q9: =VARP('Mandatory Assigment '!$I$3:$I$1563) -> 0.0004625869 | R9: {=TRANSPOSE(Q10:Q13)} -> 0.00027562771 | S9: 0.00023527608 | T9: 0.00023494104 | U9: 0.00016445868 | AI9: Excess Return | AJ9: =Q3-$W$3 -> 0.00040824625 | AK9: =R3-$W$3 -> 0.00063023905 | AL9: =S3-$W$3 -> 0.0015240008 | AM9: =T3-$W$3 -> 0.00092161713 | AN9: =U3-$W$3 -> 0.00066485382
A10: 43844 | B10: 30.31292 | C10: 88.130287 | D10: 23.528303 | E10: 13.323237 | F10: 153.58885 | I10: =B10/B9-1 -> 0.0074157033 | J10: =C10/C9-1 -> -0.0030859131 | K10: =D10/D9-1 -> 0.020670223 | L10: =E10/E9-1 -> -0.0029280332 | M10: =F10/F9-1 -> -0.0070434067 | N10: =SUMPRODUCT(I10:M10,$AJ$13:$AN$13) -> 0.0049978347 | P10: CVX | Q10: 0.00027562771 | R10: =VARP('Mandatory Assigment '!$J$3:$J$1563) -> 0.00045019868 | S10: {=TRANSPOSE(R11:R13)} -> 0.00020816322 | T10: 0.00036016018 | U10: 0.00012187847
A11: 43845 | B11: 29.75506 | C11: 88.001465 | D11: 23.408026 | E11: 13.114554 | F11: 154.58354 | I11: =B11/B10-1 -> -0.018403355 | J11: =C11/C10-1 -> -0.0014617259 | K11: =D11/D10-1 -> -0.0051120306 | L11: =E11/E10-1 -> -0.015663086 | M11: =F11/F10-1 -> 0.006476316 | N11: =SUMPRODUCT(I11:M11,$AJ$13:$AN$13) -> -0.0024466013 | P11: DELL | Q11: 0.00023527608 | R11: 0.00020816322 | S11: =VARP('Mandatory Assigment '!$K$3:$K$1563) -> 0.00085685644 | T11: {=TRANSPOSE(S12:S13)} -> 0.00019287225 | U11: 0.00023246358 | AI11: Weights z | AJ11: {=MMULT(AJ9:AN9,_xlfn.ANCHORARRAY(AJ3))} -> -0.8176613 | AK11: -0.092623626 | AL11: 1.4720409 | AM11: 1.3210233 | AN11: 0.94441168
A12: 43846 | B12: 29.797985 | C12: 88.5774 | D12: 23.750355 | E12: 13.23846 | F12: 157.41608 | I12: =B12/B11-1 -> 0.0014426078 | J12: =C12/C11-1 -> 0.0065446111 | K12: =D12/D11-1 -> 0.01462443 | L12: =E12/E11-1 -> 0.009447914 | M12: =F12/F11-1 -> 0.01832365 | N12: =SUMPRODUCT(I12:M12,$AJ$13:$AN$13) -> 0.017518446 | P12: EQNR | Q12: 0.00023494104 | R12: 0.00036016018 | S12: 0.00019287225 | T12: =VARP('Mandatory Assigment '!$L$3:$L$1563) -> 0.00057885206 | U12: 0.00010428269 | X12: g) | Y12: {=_xlfn.ANCHORARRAY(Q2)} -> BAC | Z12: CVX | AA12: DELL | AB12: EQNR | AC12: MSFT | AD12: Sum | AE12: Portf. StDev
A13: 43847 | B13: 29.789392 | C13: 87.584686 | D13: 23.287746 | E13: 13.297153 | F13: 158.29704 | I13: =B13/B12-1 -> -0.00028836197 | J13: =C13/C12-1 -> -0.011207305 | K13: =D13/D12-1 -> -0.019477955 | L13: =E13/E12-1 -> 0.0044335167 | M13: =F13/F12-1 -> 0.0055964181 | N13: =SUMPRODUCT(I13:M13,$AJ$13:$AN$13) -> -0.0057500187 | P13: MSFT | Q13: 0.00016445868 | R13: 0.00012187847 | S13: 0.00023246358 | T13: 0.00010428269 | U13: =VARP('Mandatory Assigment '!$M$3:$M$1563) -> 0.00035012103 | X13: Weights | Y13: 0.1497148 | Z13: 0.18164322 | AA13: 0.030306767 | AB13: 0.1446331 | AC13: 0.49370211 | AD13: =SUM(Y13:AC13) -> 1 | AE13: {=MMULT(MMULT(Y13:AC13,$Q$9:$U$13),TRANSPOSE(Y13:AC13))} -> 0.00024168588 | AI13: Weights x | AJ13: =AJ11/SUM(_xlfn.ANCHORARRAY($AJ$11)) -> -0.28921333 | AK13: =AK11/SUM(_xlfn.ANCHORARRAY($AJ$11)) -> -0.032761716 | AL13: =AL11/SUM(_xlfn.ANCHORARRAY($AJ$11)) -> 0.52067261 | AM13: =AM11/SUM(_xlfn.ANCHORARRAY($AJ$11)) -> 0.46725648 | AN13: =AN11/SUM(_xlfn.ANCHORARRAY($AJ$11)) -> 0.33404596
A14: 43851 | B14: 29.403189 | C14: 85.86451 | D14: 22.80201 | E14: 12.990645 | F14: 157.72867 | I14: =B14/B13-1 -> -0.012964473 | J14: =C14/C13-1 -> -0.019640154 | K14: =D14/D13-1 -> -0.020858044 | L14: =E14/E13-1 -> -0.023050582 | M14: =F14/F13-1 -> -0.0035905575 | N14: =SUMPRODUCT(I14:M14,$AJ$13:$AN$13) -> -0.018437214
A15: 43852 | B15: 29.48901 | C15: 85.553833 | D15: 23.102701 | E15: 13.042817 | F15: 156.97079 | I15: =B15/B14-1 -> 0.0029187702 | J15: =C15/C14-1 -> -0.0036182187 | K15: =D15/D14-1 -> 0.013187066 | L15: =E15/E14-1 -> 0.0040160982 | M15: =F15/F14-1 -> -0.0048049194 | N15: =SUMPRODUCT(I15:M15,$AJ$13:$AN$13) -> 0.0064120199 | P15: Corr | Q15: BAC | R15: CVX | S15: DELL | T15: EQNR | U15: MSFT | AI15: Security market line | AM15: Beta | AN15: Return
A16: 43853 | B16: 29.283037 | C16: 85.705383 | D16: 23.301626 | E16: 13.023252 | F16: 157.93704 | I16: =B16/B15-1 -> -0.0069847266 | J16: =C16/C15-1 -> 0.0017714027 | K16: =D16/D15-1 -> 0.0086104658 | L16: =E16/E15-1 -> -0.001500104 | M16: =F16/F15-1 -> 0.0061555881 | N16: =SUMPRODUCT(I16:M16,$AJ$13:$AN$13) -> 0.0078005916 | P16: BAC | Q16: 1 | R16: {=TRANSPOSE(Q17:Q20)} -> 0.60398215 | S16: 0.37370343 | T16: 0.4540236 | U16: 0.40864957 | X16: h) | Y16: {=_xlfn.ANCHORARRAY(Y12)} -> BAC | Z16: CVX | AA16: DELL | AB16: EQNR | AC16: MSFT | AD16: Sum | AE16: Portf. StDev | AF16: Return | AG16: Sharpe ratio | AI16: Inteercept | AJ16: =W3 -> 0.0001 | AL16: Point 1 | AM16: -1 | AN16: =AJ16+AJ17*AM16 -> -0.0012075108
A17: 43854 | B17: 28.785261 | C17: 84.758148 | D17: 23.12121 | E17: 12.931954 | F17: 156.34554 | I17: =B17/B16-1 -> -0.016998784 | J17: =C17/C16-1 -> -0.011052224 | K17: =D17/D16-1 -> -0.0077426402 | L17: =E17/E16-1 -> -0.0070103192 | M17: =F17/F16-1 -> -0.010076844 | N17: =SUMPRODUCT(I17:M17,$AJ$13:$AN$13) -> -0.0053947619 | P17: CVX | Q17: 0.60398215 | R17: 1 | S17: {=TRANSPOSE(R18:R20)} -> 0.33515666 | T17: 0.70552075 | U17: 0.30698404 | X17: Weights | Y17: 0 | Z17: 0.073635598 | AA17: 0.2330809 | AB17: 0.27799235 | AC17: 0.41529116 | AD17: =SUM(Y17:AC17) -> 1 | AE17: {=MMULT(MMULT(Y17:AC17,$Q$9:$U$13),TRANSPOSE(Y17:AC17))} -> 0.00027752955 | AF17: {=MMULT(Y17:AC17,TRANSPOSE(Q3:U3))} -> 0.0010339339 | AG17: =(AF17-W3)/AE17 -> 3.3651692 | AI17: Slope | AJ17: =X3 -> 0.0013075108 | AL17: Point 2 | AM17: 1.5 | AN17: =AJ16+AJ17*AM17 -> 0.0020612662
A18: 43857 | B18: 28.193077 | C18: 83.651772 | D18: 22.274637 | E18: 12.534146 | F18: 153.73097 | I18: =B18/B17-1 -> -0.020572475 | J18: =C18/C17-1 -> -0.013053337 | K18: =D18/D17-1 -> -0.036614557 | L18: =E18/E17-1 -> -0.030761636 | M18: =F18/F17-1 -> -0.016722978 | N18: =SUMPRODUCT(I18:M18,$AJ$13:$AN$13) -> -0.032646531 | P18: DELL | Q18: 0.37370343 | R18: 0.33515666 | S18: 1 | T18: =S19 -> 0.27386209 | U18: 0.42441604
A19: 43858 | B19: 28.527788 | C19: 84.204979 | D19: 22.519815 | E19: 12.5211 | F19: 156.74345 | I19: =B19/B18-1 -> 0.011872102 | J19: =C19/C18-1 -> 0.006613218 | K19: =D19/D18-1 -> 0.011007058 | L19: =E19/E18-1 -> -0.0010408579 | M19: =F19/F18-1 -> 0.019595802 | N19: =SUMPRODUCT(I19:M19,$AJ$13:$AN$13) -> 0.008140394 | P19: EQNR | Q19: 0.4540236 | R19: 0.70552075 | S19: 0.27386209 | T19: 1 | U19: 0.23164308 | X19: i) | Y19: {=_xlfn.ANCHORARRAY(Y16)} -> BAC | Z19: CVX | AA19: DELL | AB19: EQNR | AC19: MSFT | AD19: Sum | AE19: Portf. StDev | AF19: Return | AG19: Sharpe ratio
A20: 43859 | B20: 28.330391 | C20: 83.636635 | D20: 22.644724 | E20: 12.318941 | F20: 159.18752 | I20: =B20/B19-1 -> -0.006919472 | J20: =C20/C19-1 -> -0.006749531 | K20: =D20/D19-1 -> 0.0055466017 | L20: =E20/E19-1 -> -0.016145461 | M20: =F20/F19-1 -> 0.015592749 | N20: =SUMPRODUCT(I20:M20,$AJ$13:$AN$13) -> 0.0027749169 | P20: MSFT | Q20: 0.40864957 | R20: 0.30698404 | S20: 0.42441604 | T20: 0.23164308 | U20: 1 | X20: Weights | Y20: -0.016533622 | Z20: 0.10051993 | AA20: 0.21614958 | AB20: 0.26684897 | AC20: 0.43301514 | AD20: =SUM(Y20:AC20) -> 1 | AE20: {=MMULT(MMULT(Y20:AC20,$Q$9:$U$13),TRANSPOSE(Y20:AC20))} -> 0.00027339175 | AF20: {=MMULT(Y20:AC20,TRANSPOSE(Q3:U3))} -> 0.0010198383 | AG20: =(AF20-W6)/AE20 -> 3.7303184
A21: 43860 | B21: 28.733765 | C21: 84.417152 | D21: 22.843643 | E21: 12.23416 | F21: 163.67778 | I21: =B21/B20-1 -> 0.014238198 | J21: =C21/C20-1 -> 0.0093322451 | K21: =D21/D20-1 -> 0.0087843551 | L21: =E21/E20-1 -> -0.0068821413 | M21: =F21/F20-1 -> 0.028207394 | N21: =SUMPRODUCT(I21:M21,$AJ$13:$AN$13) -> 0.0063569967
A22: 43861 | B22: 28.175915 | C22: 81.18898 | D22: 22.561455 | E22: 11.855921 | F22: 161.26216 | I22: =B22/B21-1 -> -0.019414438 | J22: =C22/C21-1 -> -0.038240715 | K22: =D22/D21-1 -> -0.012353039 | L22: =E22/E21-1 -> -0.030916681 | M22: =F22/F21-1 -> -0.01475838 | N22: =SUMPRODUCT(I22:M22,$AJ$13:$AN$13) -> -0.01894014 | AM22: Portf. Return
A23: 43864 | B23: 28.296072 | C23: 80.537315 | D23: 22.751118 | E23: 11.660276 | F23: 165.19353 | I23: =B23/B22-1 -> 0.0042645374 | J23: =C23/C22-1 -> -0.0080265171 | K23: =D23/D22-1 -> 0.0084065028 | L23: =E23/E22-1 -> -0.016501829 | M23: =F23/F22-1 -> 0.024378726 | N23: =SUMPRODUCT(I23:M23,$AJ$13:$AN$13) -> 0.0038396653 | P23: c), e) and f) | Q23: {=_xlfn.ANCHORARRAY(Q2)} -> BAC | R23: CVX | S23: DELL | T23: EQNR | U23: MSFT | X23: Portf. Variance | Y23: Portf. StDev | Z23: Portf. Return | AA23: Mean Abs Dev | AB23: Value at risk 10% | AD23: d) | AE23: {=_xlfn.ANCHORARRAY(Q23)} -> BAC | AF23: CVX | AG23: DELL | AH23: EQNR | AI23: MSFT | AK23: Portf. Variance | AL23: Portf. StDev | AM23: {=MMULT(_xlfn.ANCHORARRAY(AE24),TRANSPOSE($Q$3:$U$3))} -> 0.00093475451
A24: 43865 | B24: 28.853924 | C24: 80.969238 | D24: 23.606943 | E24: 11.751575 | F24: 170.63109 | I24: =B24/B23-1 -> 0.019714814 | J24: =C24/C23-1 -> 0.005363016 | K24: =D24/D23-1 -> 0.037616852 | L24: =E24/E23-1 -> 0.0078299222 | M24: =F24/F23-1 -> 0.032916308 | N24: =SUMPRODUCT(I24:M24,$AJ$13:$AN$13) -> 0.028362717 | P24: Port 1 | Q24: {=_xlfn.LET(_xlpm.array,_xlfn.RANDARRAY(1,COLUMNS(_xlfn.ANCHORARRAY(Q23)),0,1,FALSE),_xlpm.array/SUM(_xlpm.array))} -> 0.3392248 | R24: 0.32366361 | S24: 0.040308661 | T24: 0.25011221 | U24: 0.046690715 | X24: {=MMULT(MMULT(_xlfn.ANCHORARRAY(Q24),$Q$9:$U$13),TRANSPOSE(_xlfn.ANCHORARRAY(Q24)))} -> 0.00032542157 | Y24: =SQRT(X24) -> 0.018039445 | Z24: {=MMULT(_xlfn.ANCHORARRAY(Q24),TRANSPOSE($Q$3:$U$3))} -> 0.00076545332 | AA24: =AVEDEV(Q24*$Q$3,R24*$R$3,S24*$S$3,T24*$T$3,U24*$U$3) -> 8.2003385e-05 | AB24: {=MMULT(_xlfn.ANCHORARRAY(Q24),TRANSPOSE($Q$6:$U$6))} -> -0.022325083 | AD24: Port 1 | AE24: {=_xlfn.LET(_xlpm.array,_xlfn.RANDARRAY(1,COLUMNS(_xlfn.ANCHORARRAY(Q23)),-0.5,1,FALSE),_xlpm.array/SUM(_xlpm.array))} -> 0.0074859444 | AF24: 0.25400106 | AG24: 0.12049105 | AH24: 0.30025439 | AI24: 0.31776755 | AK24: {=MMULT(MMULT(_xlfn.ANCHORARRAY(AE24),$Q$9:$U$13),TRANSPOSE(_xlfn.ANCHORARRAY(AE24)))} -> 0.00027136859 | AL24: =SQRT(AK24) -> 0.016473269 | AM24: {=MMULT(_xlfn.ANCHORARRAY(AE25),TRANSPOSE($Q$3:$U$3))} -> -0.00037433608
A25: 43866 | B25: 29.789392 | C25: 83.568436 | D25: 23.495924 | E25: 12.13634 | F25: 170.42268 | I25: =B25/B24-1 -> 0.032420848 | J25: =C25/C24-1 -> 0.032101048 | K25: =D25/D24-1 -> -0.004702817 | L25: =E25/E24-1 -> 0.032741539 | M25: =F25/F24-1 -> -0.001221375 | N25: =SUMPRODUCT(I25:M25,$AJ$13:$AN$13) -> 0.0020138462 | P25: Port 2 | Q25: {=_xlfn.LET(_xlpm.array,_xlfn.RANDARRAY(1,COLUMNS(_xlfn.ANCHORARRAY(Q24)),0,1,FALSE),_xlpm.array/SUM(_xlpm.array))} -> 0.25705872 | R25: 0.24174305 | S25: 0.17340113 | T25: 0.12322772 | U25: 0.20456938 | X25: {=MMULT(MMULT(_xlfn.ANCHORARRAY(Q25),$Q$9:$U$13),TRANSPOSE(_xlfn.ANCHORARRAY(Q25)))} -> 0.00027445101 | Y25: =SQRT(X25) -> 0.016566563 | Z25: {=MMULT(_xlfn.ANCHORARRAY(Q25),TRANSPOSE($Q$3:$U$3))} -> 0.00087114014 | AA25: =AVEDEV(Q25*$Q$3,R25*$R$3,S25*$S$3,T25*$T$3,U25*$U$3) -> 4.3871092e-05 | AB25: {=MMULT(_xlfn.ANCHORARRAY(Q25),TRANSPOSE($Q$6:$U$6))} -> -0.022460864 | AD25: Port 2 | AE25: {=_xlfn.LET(_xlpm.array,_xlfn.RANDARRAY(1,COLUMNS(_xlfn.ANCHORARRAY(Q24)),-1,1,FALSE),_xlpm.array/SUM(_xlpm.array))} -> 3.7376256 | AF25: -3.9520038 | AG25: 0.34007972 | AH25: -2.3720797 | AI25: 3.2463782 | AK25: {=MMULT(MMULT(_xlfn.ANCHORARRAY(AE25),$Q$9:$U$13),TRANSPOSE(_xlfn.ANCHORARRAY(AE25)))} -> 0.01448198 | AL25: =SQRT(AK25) -> 0.1203411 | AM25: {=MMULT(_xlfn.ANCHORARRAY(AE26),TRANSPOSE($Q$3:$U$3))} -> 0.0014423559
A26: 43867 | B26: 29.75506 | C26: 82.969765 | D26: 24.448895 | E26: 11.67332 | F26: 173.95622 | I26: =B26/B25-1 -> -0.0011525 | J26: =C26/C25-1 -> -0.0071638407 | K26: =D26/D25-1 -> 0.040558971 | L26: =E26/E25-1 -> -0.038151561 | M26: =F26/F25-1 -> 0.02073397 | N26: =SUMPRODUCT(I26:M26,$AJ$13:$AN$13) -> 0.010785498 | P26: Port 3 | Q26: {=_xlfn.LET(_xlpm.array,_xlfn.RANDARRAY(1,COLUMNS(_xlfn.ANCHORARRAY(Q25)),0,1,FALSE),_xlpm.array/SUM(_xlpm.array))} -> 0.18574909 | R26: 0.18895243 | S26: 0.11461413 | T26: 0.22835321 | U26: 0.28233115 | X26: {=MMULT(MMULT(_xlfn.ANCHORARRAY(Q26),$Q$9:$U$13),TRANSPOSE(_xlfn.ANCHORARRAY(Q26)))} -> 0.00025961571 | Y26: =SQRT(X26) -> 0.016112595 | Z26: {=MMULT(_xlfn.ANCHORARRAY(Q26),TRANSPOSE($Q$3:$U$3))} -> 0.00086775175 | AA26: =AVEDEV(Q26*$Q$3,R26*$R$3,S26*$S$3,T26*$T$3,U26*$U$3) -> 4.5885593e-05 | AB26: {=MMULT(_xlfn.ANCHORARRAY(Q26),TRANSPOSE($Q$6:$U$6))} -> -0.022447012 | AD26: Port 3 | AE26: {=_xlfn.LET(_xlpm.array,_xlfn.RANDARRAY(1,COLUMNS(_xlfn.ANCHORARRAY(Q25)),-1,1,FALSE),_xlpm.array/SUM(_xlpm.array))} -> 0.29021625 | AF26: 0.055912818 | AG26: 0.85207496 | AH26: 0.085104008 | AI26: -0.28330803 | AK26: {=MMULT(MMULT(_xlfn.ANCHORARRAY(AE26),$Q$9:$U$13),TRANSPOSE(_xlfn.ANCHORARRAY(AE26)))} -> 0.00073474734 | AL26: =SQRT(AK26) -> 0.027106223 | AM26: {=MMULT(_xlfn.ANCHORARRAY(AE27),TRANSPOSE($Q$3:$U$3))} -> 0.00065083412
A27: 43868 | B27: 29.703577 | C27: 82.55304 | D27: 23.879887 | E27: 11.268995 | F27: 174.20253 | I27: =B27/B26-1 -> -0.0017302319 | J27: =C27/C26-1 -> -0.0050226147 | K27: =D27/D26-1 -> -0.023273358 | L27: =E27/E26-1 -> -0.034636636 | M27: =F27/F26-1 -> 0.0014159159 | N27: =SUMPRODUCT(I27:M27,$AJ$13:$AN$13) -> -0.027164056 | P27: Port 4 | Q27: {=_xlfn.LET(_xlpm.array,_xlfn.RANDARRAY(1,COLUMNS(_xlfn.ANCHORARRAY(Q26)),0,1,FALSE),_xlpm.array/SUM(_xlpm.array))} -> 0.15631913 | R27: 0.26758674 | S27: 0.11986549 | T27: 0.12725984 | U27: 0.3289688 | X27: {=MMULT(MMULT(_xlfn.ANCHORARRAY(Q27),$Q$9:$U$13),TRANSPOSE(_xlfn.ANCHORARRAY(Q27)))} -> 0.00025354051 | Y27: =SQRT(X27) -> 0.015922955 | Z27: {=MMULT(_xlfn.ANCHORARRAY(Q27),TRANSPOSE($Q$3:$U$3))} -> 0.00085113642 | AA27: =AVEDEV(Q27*$Q$3,R27*$R$3,S27*$S$3,T27*$T$3,U27*$U$3) -> 5.2398048e-05 | AB27: {=MMULT(_xlfn.ANCHORARRAY(Q27),TRANSPOSE($Q$6:$U$6))} -> -0.021968369 | AD27: Port 4 | AE27: {=_xlfn.LET(_xlpm.array,_xlfn.RANDARRAY(1,COLUMNS(_xlfn.ANCHORARRAY(Q26)),-1,1,FALSE),_xlpm.array/SUM(_xlpm.array))} -> 0.23216729 | AF27: 0.35139931 | AG27: -0.04835459 | AH27: -0.0028684198 | AI27: 0.46765641 | AK27: {=MMULT(MMULT(_xlfn.ANCHORARRAY(AE27),$Q$9:$U$13),TRANSPOSE(_xlfn.ANCHORARRAY(AE27)))} -> 0.00025571341 | AL27: =SQRT(AK27) -> 0.015991042 | AM27: {=MMULT(_xlfn.ANCHORARRAY(AE28),TRANSPOSE($Q$3:$U$3))} -> 0.0014321704
A28: 43871 | B28: 29.77223 | C28: 83.197136 | D28: 24.106565 | E28: 10.903793 | F28: 178.75906 | I28: =B28/B27-1 -> 0.002311274 | J28: =C28/C27-1 -> 0.0078022127 | K28: =D28/D27-1 -> 0.0094924591 | L28: =E28/E27-1 -> -0.032407676 | M28: =F28/F27-1 -> 0.026156531 | N28: =SUMPRODUCT(I28:M28,$AJ$13:$AN$13) -> -0.002386815 | P28: Port 5 | Q28: {=_xlfn.LET(_xlpm.array,_xlfn.RANDARRAY(1,COLUMNS(_xlfn.ANCHORARRAY(Q27)),0,1,FALSE),_xlpm.array/SUM(_xlpm.array))} -> 0.37166384 | R28: 0.24116581 | S28: 0.075019812 | T28: 0.29477086 | U28: 0.017379685 | X28: {=MMULT(MMULT(_xlfn.ANCHORARRAY(Q28),$Q$9:$U$13),TRANSPOSE(_xlfn.ANCHORARRAY(Q28)))} -> 0.00033140622 | Y28: =SQRT(X28) -> 0.018204566 | Z28: {=MMULT(_xlfn.ANCHORARRAY(Q28),TRANSPOSE($Q$3:$U$3))} -> 0.00080127355 | AA28: =AVEDEV(Q28*$Q$3,R28*$R$3,S28*$S$3,T28*$T$3,U28*$U$3) -> 7.4153708e-05 | AB28: {=MMULT(_xlfn.ANCHORARRAY(Q28),TRANSPOSE($Q$6:$U$6))} -> -0.022802873 | AD28: Port 5 | AE28: {=_xlfn.LET(_xlpm.array,_xlfn.RANDARRAY(1,COLUMNS(_xlfn.ANCHORARRAY(Q27)),-1,1,FALSE),_xlpm.array/SUM(_xlpm.array))} -> 0.053747507 | AF28: -0.43429787 | AG28: 0.67695961 | AH28: 0.3289711 | AI28: 0.37461966 | AK28: {=MMULT(MMULT(_xlfn.ANCHORARRAY(AE28),$Q$9:$U$13),TRANSPOSE(_xlfn.ANCHORARRAY(AE28)))} -> 0.00057443328 | AL28: =SQRT(AK28) -> 0.023967338 | AM28: {=MMULT(_xlfn.ANCHORARRAY(AE29),TRANSPOSE($Q$3:$U$3))} -> 0.00027926606
A29: 43872 | B29: 29.840889 | C29: 84.27317 | D29: 24.175957 | E29: 11.242907 | F29: 174.7235 | I29: =B29/B28-1 -> 0.0023061366 | J29: =C29/C28-1 -> 0.012933553 | K29: =D29/D28-1 -> 0.0028785208 | L29: =E29/E28-1 -> 0.031100483 | M29: =F29/F28-1 -> -0.022575461 | N29: =SUMPRODUCT(I29:M29,$AJ$13:$AN$13) -> 0.0073987368 | P29: Port 6 | Q29: {=_xlfn.LET(_xlpm.array,_xlfn.RANDARRAY(1,COLUMNS(_xlfn.ANCHORARRAY(Q28)),0,1,FALSE),_xlpm.array/SUM(_xlpm.array))} -> 0.1664918 | R29: 0.096590332 | S29: 0.097192105 | T29: 0.4729712 | U29: 0.16675456 | X29: {=MMULT(MMULT(_xlfn.ANCHORARRAY(Q29),$Q$9:$U$13),TRANSPOSE(_xlfn.ANCHORARRAY(Q29)))} -> 0.00030941458 | Y29: =SQRT(X29) -> 0.017590184 | Z29: {=MMULT(_xlfn.ANCHORARRAY(Q29),TRANSPOSE($Q$3:$U$3))} -> 0.00092373126 | AA29: =AVEDEV(Q29*$Q$3,R29*$R$3,S29*$S$3,T29*$T$3,U29*$U$3) -> 0.00011937969 | AB29: {=MMULT(_xlfn.ANCHORARRAY(Q29),TRANSPOSE($Q$6:$U$6))} -> -0.023484229 | AD29: Port 6 | AE29: {=_xlfn.LET(_xlpm.array,_xlfn.RANDARRAY(1,COLUMNS(_xlfn.ANCHORARRAY(Q28)),-1,1,FALSE),_xlpm.array/SUM(_xlpm.array))} -> -9.2046111 | AF29: 8.7494237 | AG29: -4.4968802 | AH29: 5.1361682 | AI29: 0.81589943 | AK29: {=MMULT(MMULT(_xlfn.ANCHORARRAY(AE29),$Q$9:$U$13),TRANSPOSE(_xlfn.ANCHORARRAY(AE29)))} -> 0.064872792 | AL29: =SQRT(AK29) -> 0.25470138 | AM29: {=MMULT(_xlfn.ANCHORARRAY(AE30),TRANSPOSE($Q$3:$U$3))} -> 0.0015326292
A30: 43873 | B30: 29.969624 | C30: 84.902145 | D30: 24.657072 | E30: 11.438548 | F30: 174.97932 | I30: =B30/B29-1 -> 0.0043140333 | J30: =C30/C29-1 -> 0.007463525 | K30: =D30/D29-1 -> 0.019900571 | L30: =E30/E29-1 -> 0.017401329 | M30: =F30/F29-1 -> 0.0014641926 | N30: =SUMPRODUCT(I30:M30,$AJ$13:$AN$13) -> 0.01748948 | P30: Port 7 | Q30: {=_xlfn.LET(_xlpm.array,_xlfn.RANDARRAY(1,COLUMNS(_xlfn.ANCHORARRAY(Q29)),0,1,FALSE),_xlpm.array/SUM(_xlpm.array))} -> 0.2099764 | R30: 0.050927481 | S30: 0.2843357 | T30: 0.25207584 | U30: 0.20268458 | X30: {=MMULT(MMULT(_xlfn.ANCHORARRAY(Q30),$Q$9:$U$13),TRANSPOSE(_xlfn.ANCHORARRAY(Q30)))} -> 0.00029774977 | Y30: =SQRT(X30) -> 0.017255427 | Z30: {=MMULT(_xlfn.ANCHORARRAY(Q30),TRANSPOSE($Q$3:$U$3))} -> 0.0010182194 | AA30: =AVEDEV(Q30*$Q$3,R30*$R$3,S30*$S$3,T30*$T$3,U30*$U$3) -> 0.00012479945 | AB30: {=MMULT(_xlfn.ANCHORARRAY(Q30),TRANSPOSE($Q$6:$U$6))} -> -0.023729182 | AD30: Port 7 | AE30: {=_xlfn.LET(_xlpm.array,_xlfn.RANDARRAY(1,COLUMNS(_xlfn.ANCHORARRAY(Q29)),-1,1,FALSE),_xlpm.array/SUM(_xlpm.array))} -> 0.33169562 | AF30: 0.30575114 | AG30: 0.81646899 | AH30: 0.63096119 | AI30: -1.0848769 | AK30: {=MMULT(MMULT(_xlfn.ANCHORARRAY(AE30),$Q$9:$U$13),TRANSPOSE(_xlfn.ANCHORARRAY(AE30)))} -> 0.0012762001 | AL30: =SQRT(AK30) -> 0.035723943 | AM30: {=MMULT(_xlfn.ANCHORARRAY(AE31),TRANSPOSE($Q$3:$U$3))} -> 0.0025735031
A31: 43874 | B31: 29.961056 | C31: 84.614182 | D31: 24.310116 | E31: 11.39942 | F31: 174.03203 | I31: =B31/B30-1 -> -0.00028588314 | J31: =C31/C30-1 -> -0.0033917148 | K31: =D31/D30-1 -> -0.014071267 | L31: =E31/E30-1 -> -0.0034207404 | M31: =F31/F30-1 -> -0.0054137604 | N31: =SUMPRODUCT(I31:M31,$AJ$13:$AN$13) -> -0.010539532 | P31: Port 8 | Q31: {=_xlfn.LET(_xlpm.array,_xlfn.RANDARRAY(1,COLUMNS(_xlfn.ANCHORARRAY(Q30)),0,1,FALSE),_xlpm.array/SUM(_xlpm.array))} -> 0.10199625 | R31: 0.26183543 | S31: 0.27859795 | T31: 0.27560895 | U31: 0.08196143 | X31: {=MMULT(MMULT(_xlfn.ANCHORARRAY(Q31),$Q$9:$U$13),TRANSPOSE(_xlfn.ANCHORARRAY(Q31)))} -> 0.00032508578 | Y31: =SQRT(X31) -> 0.018030135 | Z31: {=MMULT(_xlfn.ANCHORARRAY(Q31),TRANSPOSE($Q$3:$U$3))} -> 0.0010397403 | AA31: =AVEDEV(Q31*$Q$3,R31*$R$3,S31*$S$3,T31*$T$3,U31*$U$3) -> 0.0001272456 | AB31: {=MMULT(_xlfn.ANCHORARRAY(Q31),TRANSPOSE($Q$6:$U$6))} -> -0.023746654 | AD31: Port 8 | AE31: {=_xlfn.LET(_xlpm.array,_xlfn.RANDARRAY(1,COLUMNS(_xlfn.ANCHORARRAY(Q30)),-1,1,FALSE),_xlpm.array/SUM(_xlpm.array))} -> -1.8064437 | AF31: -1.1247555 | AG31: 1.0942059 | AH31: 1.4257698 | AI31: 1.4112235 | AK31: {=MMULT(MMULT(_xlfn.ANCHORARRAY(AE31),$Q$9:$U$13),TRANSPOSE(_xlfn.ANCHORARRAY(AE31)))} -> 0.0028051183 | AL31: =SQRT(AK31) -> 0.052963368 | AM31: {=MMULT(_xlfn.ANCHORARRAY(AE32),TRANSPOSE($Q$3:$U$3))} -> 0.0020258622
A32: 43875 | B32: 29.909559 | C32: 84.391861 | D32: 24.462776 | E32: 11.379856 | F32: 175.58562 | I32: =B32/B31-1 -> -0.0017187814 | J32: =C32/C31-1 -> -0.0026274621 | K32: =D32/D31-1 -> 0.0062797056 | L32: =E32/E31-1 -> -0.0017161992 | M32: =F32/F31-1 -> 0.0089270285 | N32: =SUMPRODUCT(I32:M32,$AJ$13:$AN$13) -> 0.0060329779 | P32: Port 9 | Q32: {=_xlfn.LET(_xlpm.array,_xlfn.RANDARRAY(1,COLUMNS(_xlfn.ANCHORARRAY(Q31)),0,1,FALSE),_xlpm.array/SUM(_xlpm.array))} -> 0.25063527 | R32: 0.1890797 | S32: 0.11103288 | T32: 0.16120323 | U32: 0.28804891 | X32: {=MMULT(MMULT(_xlfn.ANCHORARRAY(Q32),$Q$9:$U$13),TRANSPOSE(_xlfn.ANCHORARRAY(Q32)))} -> 0.00025719072 | Y32: =SQRT(X32) -> 0.016037167 | Z32: {=MMULT(_xlfn.ANCHORARRAY(Q32),TRANSPOSE($Q$3:$U$3))} -> 0.00083077859 | AA32: =AVEDEV(Q32*$Q$3,R32*$R$3,S32*$S$3,T32*$T$3,U32*$U$3) -> 2.7328541e-05 | AB32: {=MMULT(_xlfn.ANCHORARRAY(Q32),TRANSPOSE($Q$6:$U$6))} -> -0.022179878 | AD32: Port 9 | AE32: {=_xlfn.LET(_xlpm.array,_xlfn.RANDARRAY(1,COLUMNS(_xlfn.ANCHORARRAY(Q31)),-1,1,FALSE),_xlpm.array/SUM(_xlpm.array))} -> -0.45461872 | AF32: 0.65570149 | AG32: 1.8307029 | AH32: -1.5804284 | AI32: 0.54864276 | AK32: {=MMULT(MMULT(_xlfn.ANCHORARRAY(AE32),$Q$9:$U$13),TRANSPOSE(_xlfn.ANCHORARRAY(AE32)))} -> 0.0034227738 | AL32: =SQRT(AK32) -> 0.058504477 | AM32: {=MMULT(_xlfn.ANCHORARRAY(AE33),TRANSPOSE($Q$3:$U$3))} -> -0.0021020153
A33: 43879 | B33: 29.411774 | C33: 84.514519 | D33: 24.411888 | E33: 11.333517 | F33: 177.36653 | I33: =B33/B32-1 -> -0.016643026 | J33: =C33/C32-1 -> 0.0014534313 | K33: =D33/D32-1 -> -0.0020802243 | L33: =E33/E32-1 -> -0.0040720229 | M33: =F33/F32-1 -> 0.010142712 | N33: =SUMPRODUCT(I33:M33,$AJ$13:$AN$13) -> 0.005168105 | P33: Port 10 | Q33: {=_xlfn.LET(_xlpm.array,_xlfn.RANDARRAY(1,COLUMNS(_xlfn.ANCHORARRAY(Q32)),0,1,FALSE),_xlpm.array/SUM(_xlpm.array))} -> 0.06266235 | R33: 0.36136191 | S33: 0.41845572 | T33: 0.080127873 | U33: 0.077392143 | X33: {=MMULT(MMULT(_xlfn.ANCHORARRAY(Q33),$Q$9:$U$13),TRANSPOSE(_xlfn.ANCHORARRAY(Q33)))} -> 0.00036514597 | Y33: =SQRT(X33) -> 0.019108793 | Z33: {=MMULT(_xlfn.ANCHORARRAY(Q33),TRANSPOSE($Q$3:$U$3))} -> 0.0011163546 | AA33: =AVEDEV(Q33*$Q$3,R33*$R$3,S33*$S$3,T33*$T$3,U33*$U$3) -> 0.00019876446 | AB33: {=MMULT(_xlfn.ANCHORARRAY(Q33),TRANSPOSE($Q$6:$U$6))} -> -0.023733178 | AD33: Port 10 | AE33: {=_xlfn.LET(_xlpm.array,_xlfn.RANDARRAY(1,COLUMNS(_xlfn.ANCHORARRAY(Q32)),-1,1,FALSE),_xlpm.array/SUM(_xlpm.array))} -> 2.1979278 | AF33: 1.6527453 | AG33: -2.8211772 | AH33: 0.69383364 | AI33: -0.72332953 | AK33: {=MMULT(MMULT(_xlfn.ANCHORARRAY(AE33),$Q$9:$U$13),TRANSPOSE(_xlfn.ANCHORARRAY(AE33)))} -> 0.0087068442 | AL33: =SQRT(AK33) -> 0.093310472 | AM33: {=MMULT(_xlfn.ANCHORARRAY(AE34),TRANSPOSE($Q$3:$U$3))} -> 0.00096915253
A34: 43880 | B34: 29.797985 | C34: 84.897812 | D34: 24.675575 | E34: 11.479157 | F34: 177.89848 | I34: =B34/B33-1 -> 0.013131183 | J34: =C34/C33-1 -> 0.0045352344 | K34: =D34/D33-1 -> 0.010801587 | L34: =E34/E33-1 -> 0.012850413 | M34: =F34/F33-1 -> 0.0029991673 | N34: =SUMPRODUCT(I34:M34,$AJ$13:$AN$13) -> 0.0086840935 | P34: Port 11 | Q34: {=_xlfn.LET(_xlpm.array,_xlfn.RANDARRAY(1,COLUMNS(_xlfn.ANCHORARRAY(Q33)),0,1,FALSE),_xlpm.array/SUM(_xlpm.array))} -> 0.29178611 | R34: 0.18943146 | S34: 0.11629748 | T34: 0.16001919 | U34: 0.24246576 | X34: {=MMULT(MMULT(_xlfn.ANCHORARRAY(Q34),$Q$9:$U$13),TRANSPOSE(_xlfn.ANCHORARRAY(Q34)))} -> 0.00026476476 | Y34: =SQRT(X34) -> 0.016271594 | Z34: {=MMULT(_xlfn.ANCHORARRAY(Q34),TRANSPOSE($Q$3:$U$3))} -> 0.00082442585 | AA34: =AVEDEV(Q34*$Q$3,R34*$R$3,S34*$S$3,T34*$T$3,U34*$U$3) -> 1.7819089e-05 | AB34: {=MMULT(_xlfn.ANCHORARRAY(Q34),TRANSPOSE($Q$6:$U$6))} -> -0.022271921 | AD34: Port 11 | AE34: {=_xlfn.LET(_xlpm.array,_xlfn.RANDARRAY(1,COLUMNS(_xlfn.ANCHORARRAY(Q33)),-1,1,FALSE),_xlpm.array/SUM(_xlpm.array))} -> 0.36166274 | AF34: 0.18377277 | AG34: 0.39783656 | AH34: -0.14929977 | AI34: 0.20602771 | AK34: {=MMULT(MMULT(_xlfn.ANCHORARRAY(AE34),$Q$9:$U$13),TRANSPOSE(_xlfn.ANCHORARRAY(AE34)))} -> 0.00037125701 | AL34: =SQRT(AK34) -> 0.019268031 | AM34: {=MMULT(_xlfn.ANCHORARRAY(AE35),TRANSPOSE($Q$3:$U$3))} -> 0.00077132958
A35: 43881 | B35: 29.909559 | C35: 84.184853 | D35: 24.495159 | E35: 11.446057 | F35: 175.18179 | I35: =B35/B34-1 -> 0.0037443529 | J35: =C35/C34-1 -> -0.0083978524 | K35: =D35/D34-1 -> -0.0073115259 | L35: =E35/E34-1 -> -0.0028834981 | M35: =F35/F34-1 -> -0.015271013 | N35: =SUMPRODUCT(I35:M35,$AJ$13:$AN$13) -> -0.011063253 | P35: Port 12 | Q35: {=_xlfn.LET(_xlpm.array,_xlfn.RANDARRAY(1,COLUMNS(_xlfn.ANCHORARRAY(Q34)),0,1,FALSE),_xlpm.array/SUM(_xlpm.array))} -> 0.33356658 | R35: 0.19655592 | S35: 0.30541287 | T35: 0.048284688 | U35: 0.11617995 | X35: {=MMULT(MMULT(_xlfn.ANCHORARRAY(Q35),$Q$9:$U$13),TRANSPOSE(_xlfn.ANCHORARRAY(Q35)))} -> 0.00032000978 | Y35: =SQRT(X35) -> 0.017888817 | Z35: {=MMULT(_xlfn.ANCHORARRAY(Q35),TRANSPOSE($Q$3:$U$3))} -> 0.00094724664 | AA35: =AVEDEV(Q35*$Q$3,R35*$R$3,S35*$S$3,T35*$T$3,U35*$U$3) -> 0.00012261656 | AB35: {=MMULT(_xlfn.ANCHORARRAY(Q35),TRANSPOSE($Q$6:$U$6))} -> -0.023102496 | AD35: Port 12 | AE35: {=_xlfn.LET(_xlpm.array,_xlfn.RANDARRAY(1,COLUMNS(_xlfn.ANCHORARRAY(Q34)),-1,1,FALSE),_xlpm.array/SUM(_xlpm.array))} -> 0.79779602 | AF35: -0.72510134 | AG35: 0.075839764 | AH35: 0.47101569 | AI35: 0.38044987 | AK35: {=MMULT(MMULT(_xlfn.ANCHORARRAY(AE35),$Q$9:$U$13),TRANSPOSE(_xlfn.ANCHORARRAY(AE35)))} -> 0.00042955385 | AL35: =SQRT(AK35) -> 0.020725681 | AM35: {=MMULT(_xlfn.ANCHORARRAY(AE36),TRANSPOSE($Q$3:$U$3))} -> 0.0011665919
A36: 43882 | B36: 29.48901 | C36: 83.571541 | D36: 23.926149 | E36: 11.346755 | F36: 169.64383 | I36: =B36/B35-1 -> -0.014060702 | J36: =C36/C35-1 -> -0.0072852983 | K36: =D36/D35-1 -> -0.023229479 | L36: =E36/E35-1 -> -0.0086756766 | M36: =F36/F35-1 -> -0.031612668 | N36: =SUMPRODUCT(I36:M36,$AJ$13:$AN$13) -> -0.022403582 | P36: Port 13 | Q36: {=_xlfn.LET(_xlpm.array,_xlfn.RANDARRAY(1,COLUMNS(_xlfn.ANCHORARRAY(Q35)),0,1,FALSE),_xlpm.array/SUM(_xlpm.array))} -> 0.29643981 | R36: 0.12942121 | S36: 0.25465815 | T36: 0.14448776 | U36: 0.17499306 | X36: {=MMULT(MMULT(_xlfn.ANCHORARRAY(Q36),$Q$9:$U$13),TRANSPOSE(_xlfn.ANCHORARRAY(Q36)))} -> 0.00029332277 | Y36: =SQRT(X36) -> 0.017126668 | Z36: {=MMULT(_xlfn.ANCHORARRAY(Q36),TRANSPOSE($Q$3:$U$3))} -> 0.00094019317 | AA36: =AVEDEV(Q36*$Q$3,R36*$R$3,S36*$S$3,T36*$T$3,U36*$U$3) -> 9.0210562e-05 | AB36: {=MMULT(_xlfn.ANCHORARRAY(Q36),TRANSPOSE($Q$6:$U$6))} -> -0.023143959 | AD36: Port 13 | AE36: {=_xlfn.LET(_xlpm.array,_xlfn.RANDARRAY(1,COLUMNS(_xlfn.ANCHORARRAY(Q35)),-1,1,FALSE),_xlpm.array/SUM(_xlpm.array))} -> -0.13817013 | AF36: 0.1968889 | AG36: 0.21271836 | AH36: 0.74131121 | AI36: -0.012748351 | AK36: {=MMULT(MMULT(_xlfn.ANCHORARRAY(AE36),$Q$9:$U$13),TRANSPOSE(_xlfn.ANCHORARRAY(AE36)))} -> 0.00048639617 | AL36: =SQRT(AK36) -> 0.022054391 | AM36: {=MMULT(_xlfn.ANCHORARRAY(AE37),TRANSPOSE($Q$3:$U$3))} -> 0.0015744491
... A1022: 45314 | B1022: 31.057819 | C1022: 128.92522 | D1022: 79.731644 | E1022: 23.329903 | F1022: 392.14474 | I1022: =B1022/B1021-1 -> 0.0067588418 | J1022: =C1022/C1021-1 -> -0.0028071429 | K1022: =D1022/D1021-1 -> 0.015898256 | L1022: =E1022/E1021-1 -> 0.0053456403 | M1022: =F1022/F1021-1 -> 0.0060275695 | N1022: =SUMPRODUCT(I1022:M1022,$AJ$13:$AN$13) -> 0.010926277 | P1022: Port 999 | Q1022: {=_xlfn.LET(_xlpm.array,_xlfn.RANDARRAY(1,COLUMNS(_xlfn.ANCHORARRAY(Q1021)),0,1,FALSE),_xlpm.array/SUM(_xlpm.array))} -> 0.055105368 | R1022: 0.19101736 | S1022: 0.066020033 | T1022: 0.33307201 | U1022: 0.35478523 | X1022: {=MMULT(MMULT(_xlfn.ANCHORARRAY(Q1022),$Q$9:$U$13),TRANSPOSE(_xlfn.ANCHORARRAY(Q1022)))} -> 0.00026403861 | Y1022: =SQRT(X1022) -> 0.016249265 | Z1022: {=MMULT(_xlfn.ANCHORARRAY(Q1022),TRANSPOSE($Q$3:$U$3))} -> 0.00088634292 | AA1022: =AVEDEV(Q1022*$Q$3,R1022*$R$3,S1022*$S$3,T1022*$T$3,U1022*$U$3) -> 0.0001028375 | AB1022: {=MMULT(_xlfn.ANCHORARRAY(Q1022),TRANSPOSE($Q$6:$U$6))} -> -0.022440668 | AD1022: Port 999 | AE1022: {=_xlfn.LET(_xlpm.array,_xlfn.RANDARRAY(1,COLUMNS(_xlfn.ANCHORARRAY(Q1021)),-1,1,FALSE),_xlpm.array/SUM(_xlpm.array))} -> -0.25483913 | AF1022: -2.2539098 | AG1022: -2.2331445 | AH1022: 1.1055849 | AI1022: 4.6363086 | AK1022: {=MMULT(MMULT(_xlfn.ANCHORARRAY(AE1022),$Q$9:$U$13),TRANSPOSE(_xlfn.ANCHORARRAY(AE1022)))} -> 0.0079434912 | AL1022: =SQRT(AK1022) -> 0.089126266 | AM1022: {=MMULT(_xlfn.ANCHORARRAY(AE1023),TRANSPOSE($Q$3:$U$3))} -> 0.0032205165
A1023: 45315 | B1023: 31.256847 | C1023: 131.493 | D1023: 80.969749 | E1023: 23.578005 | F1023: 395.7428 | I1023: =B1023/B1022-1 -> 0.0064083062 | J1023: =C1023/C1022-1 -> 0.019916814 | K1023: =D1023/D1022-1 -> 0.015528412 | L1023: =E1023/E1022-1 -> 0.010634515 | M1023: =F1023/F1022-1 -> 0.0091753186 | N1023: =SUMPRODUCT(I1023:M1023,$AJ$13:$AN$13) -> 0.013613366 | P1023: Port 1000 | Q1023: {=_xlfn.LET(_xlpm.array,_xlfn.RANDARRAY(1,COLUMNS(_xlfn.ANCHORARRAY(Q1022)),0,1,FALSE),_xlpm.array/SUM(_xlpm.array))} -> 0.23944765 | R1023: 0.077715555 | S1023: 0.23153534 | T1023: 0.26035532 | U1023: 0.19094614 | X1023: {=MMULT(MMULT(_xlfn.ANCHORARRAY(Q1023),$Q$9:$U$13),TRANSPOSE(_xlfn.ANCHORARRAY(Q1023)))} -> 0.00028771701 | Y1023: =SQRT(X1023) -> 0.016962223 | Z1023: {=MMULT(_xlfn.ANCHORARRAY(Q1023),TRANSPOSE($Q$3:$U$3))} -> 0.00096649221 | AA1023: =AVEDEV(Q1023*$Q$3,R1023*$R$3,S1023*$S$3,T1023*$T$3,U1023*$U$3) -> 0.00010216006 | AB1023: {=MMULT(_xlfn.ANCHORARRAY(Q1023),TRANSPOSE($Q$6:$U$6))} -> -0.02345629 | AD1023: Port 1000 | AE1023: {=_xlfn.LET(_xlpm.array,_xlfn.RANDARRAY(1,COLUMNS(_xlfn.ANCHORARRAY(Q1022)),-1,1,FALSE),_xlpm.array/SUM(_xlpm.array))} -> -2.3834714 | AF1023: 1.586777 | AG1023: 2.1488406 | AH1023: 0.20564443 | AI1023: -0.5577907 | AK1023: {=MMULT(MMULT(_xlfn.ANCHORARRAY(AE1023),$Q$9:$U$13),TRANSPOSE(_xlfn.ANCHORARRAY(AE1023)))} -> 0.0045916424 | AL1023: =SQRT(AK1023) -> 0.067761659
A1024: 45316 | B1024: 31.645428 | C1024: 134.80482 | D1024: 80.321693 | E1024: 23.859188 | F1024: 398.01367 | I1024: =B1024/B1023-1 -> 0.012431846 | J1024: =C1024/C1023-1 -> 0.02518635 | K1024: =D1024/D1023-1 -> -0.0080036808 | L1024: =E1024/E1023-1 -> 0.011925659 | M1024: =F1024/F1023-1 -> 0.0057382574 | N1024: =SUMPRODUCT(I1024:M1024,$AJ$13:$AN$13) -> -0.0010987181
A1025: 45317 | B1025: 31.683331 | C1025: 135.32201 | D1025: 81.463058 | E1025: 24.132101 | F1025: 397.08963 | I1025: =B1025/B1024-1 -> 0.0011977349 | J1025: =C1025/C1024-1 -> 0.0038365199 | K1025: =D1025/D1024-1 -> 0.014209923 | L1025: =E1025/E1024-1 -> 0.011438486 | M1025: =F1025/F1024-1 -> -0.0023216332 | N1025: =SUMPRODUCT(I1025:M1025,$AJ$13:$AN$13) -> 0.0114958
...
